Workbook

Sheet experiment_data
A1: user_id | B1: signup_date | C1: experiment_group | D1: region | E1: device_type | F1: traffic_source | G1: plan_type | H1: visited_landing_page | I1: started_trial | J1: completed_onboarding | K1: converted_to_paid | L1: revenue_30d | M1: support_tickets_30d | N1: refund_requested | O1: days_to_convert | P1: engagement_score | Q1: Duplicate_User_ID | R1: Invalid_binary_values
A2: USR-100001 | B2: 45732 | C2: Control | D2: North | E2: Desktop | F2: Email | G2: Basic | H2: 0 | I2: 0 | J2: 0 | K2: 0 | L2: 0 | M2: 0 | N2: 0 | P2: 45.7 | Q2: =COUNTIF($A$2:A2,A2)>1 -> FALSE
A3: USR-100002 | B3: 45724 | C3: Control | D3: West | E3: Mobile | F3: Organic | G3: Free | H3: 1 | I3: 0 | J3: 0 | K3: 0 | L3: 0 | M3: 0 | N3: 0 | P3: 48.6 | Q3: =COUNTIF($A$2:A3,A3)>1 -> FALSE
A4: USR-100003 | B4: 45771 | C4: Control | D4: East | E4: Mobile | F4: Paid Search | G4: Premium | H4: 1 | I4: 0 | J4: 0 | K4: 0 | L4: 0 | M4: 1 | N4: 0 | P4: 35.4 | Q4: =COUNTIF($A$2:A4,A4)>1 -> FALSE
A5: USR-100004 | B5: 45781 | C5: Control | D5: South | E5: Mobile | F5: Email | G5: Basic | H5: 1 | I5: 0 | J5: 0 | K5: 0 | L5: 0 | M5: 0 | N5: 0 | P5: 64.6 | Q5: =COUNTIF($A$2:A5,A5)>1 -> FALSE
A6: USR-100005 | B6: 45700 | C6: Control | D6: North | E6: Tablet | F6: Organic | G6: Free | H6: 0 | I6: 0 | J6: 0 | K6: 0 | L6: 0 | M6: 0 | N6: 0 | P6: 66.6 | Q6: =COUNTIF($A$2:A6,A6)>1 -> FALSE
A7: USR-100006 | B7: 45685 | C7: Control | D7: East | E7: Mobile | F7: Organic | G7: Premium | H7: 1 | I7: 0 | J7: 0 | K7: 0 | L7: 0 | M7: 0 | N7: 0 | P7: 40.8 | Q7: =COUNTIF($A$2:A7,A7)>1 -> FALSE
A8: USR-100007 | B8: 45755 | C8: Control | D8: East | E8: Mobile | F8: Paid Search | G8: Basic | H8: 1 | I8: 1 | J8: 0 | K8: 0 | L8: 0 | M8: 0 | N8: 0 | P8: 57.1 | Q8: =COUNTIF($A$2:A8,A8)>1 -> FALSE
A9: USR-100008 | B9: 45794 | C9: Control | D9: South | E9: Mobile | F9: Paid Search | G9: Free | H9: 0 | I9: 0 | J9: 0 | K9: 0 | L9: 0 | M9: 0 | N9: 0 | P9: 36.4 | Q9: =COUNTIF($A$2:A9,A9)>1 -> FALSE
A10: USR-100009 | B10: 45711 | C10: Control | D10: South | E10: Tablet | F10: Referral | G10: Basic | H10: 0 | I10: 0 | J10: 0 | K10: 0 | L10: 0 | M10: 0 | N10: 0 | P10: 55.4 | Q10: =COUNTIF($A$2:A10,A10)>1 -> FALSE
A11: USR-100010 | B11: 45806 | C11: Control | D11: West | E11: Desktop | F11: Social | G11: Free | H11: 1 | I11: 0 | J11: 0 | K11: 0 | L11: 0 | M11: 0 | N11: 0 | P11: 57.3 | Q11: =COUNTIF($A$2:A11,A11)>1 -> FALSE
A12: USR-100011 | B12: 45777 | C12: Control | D12: East | E12: Mobile | F12: Paid Search | G12: Basic | H12: 1 | I12: 1 | J12: 1 | K12: 0 | L12: 0 | M12: 0 | N12: 0 | P12: 63.6 | Q12: =COUNTIF($A$2:A12,A12)>1 -> FALSE
A13: USR-100012 | B13: 45732 | C13: Control | D13: East | E13: Mobile | F13: Social | G13: Premium | H13: 1 | I13: 1 | J13: 1 | K13: 0 | L13: 0 | M13: 1 | N13: 0 | P13: 80.4 | Q13: =COUNTIF($A$2:A13,A13)>1 -> FALSE
... A60: USR-100059 | B60: 45761 | C60: Control | D60: North | E60: Mobile | F60: Social | G60: Free | H60: 0 | I60: 0 | J60: 0 | K60: 0 | L60: 0 | M60: 2 | N60: 0 | P60: 48.9 | Q60: =COUNTIF($A$2:A60,A60)>1 -> FALSE
A61: USR-100060 | B61: 45658 | C61: Control | D61: West | E61: Mobile | F61: Social | G61: Free | H61: 1 | I61: 1 | J61: 1 | K61: 1 | L61: 240.42 | M61: 0 | N61: 0 | O61: 16 | P61: 56.5 | Q61: =COUNTIF($A$2:A61,A61)>1 -> FALSE
A62: USR-100061 | B62: 45749 | C62: Control | D62: South | E62: Mobile | F62: Referral | G62: Free | H62: 1 | I62: 0 | J62: 0 | K62: 0 | L62: 0 | M62: 0 | N62: 0 | P62: 53.7 | Q62: =COUNTIF($A$2:A62,A62)>1 -> FALSE
A63: USR-100062 | B63: 45745 | C63: Control | D63: North | E63: Mobile | F63: Social | G63: Premium | H63: 0 | I63: 0 | J63: 0 | K63: 0 | L63: 0 | M63: 0 | N63: 0 | P63: 62.2 | Q63: =COUNTIF($A$2:A63,A63)>1 -> FALSE
A64: USR-100063 | B64: 45792 | C64: Control | D64: South | E64: Desktop | F64: Organic | G64: Free | H64: 1 | I64: 0 | J64: 0 | K64: 0 | L64: 0 | M64: 0 | N64: 0 | P64: 50.2 | Q64: =COUNTIF($A$2:A64,A64)>1 -> FALSE
A65: USR-100064 | B65: 45758 | C65: Control | D65: North | E65: Mobile | F65: Organic | G65: Basic | H65: 1 | I65: 0 | J65: 0 | K65: 0 | L65: 0 | M65: 0 | N65: 0 | P65: 74.3 | Q65: =COUNTIF($A$2:A65,A65)>1 -> FALSE
A66: USR-100065 | B66: 45723 | C66: Control | D66: South | E66: Desktop | F66: Paid Search | G66: Free | H66: 1 | I66: 0 | J66: 0 | K66: 0 | L66: 0 | M66: 0 | N66: 0 | P66: 58 | Q66: =COUNTIF($A$2:A66,A66)>1 -> FALSE
A67: USR-100066 | B67: 45807 | C67: Control | D67: South | E67: Mobile | F67: Organic | G67: Free | H67: 0 | I67: 0 | J67: 0 | K67: 0 | L67: 0 | M67: 0 | N67: 0 | P67: 46.7 | Q67: =COUNTIF($A$2:A67,A67)>1 -> FALSE
A68: USR-100067 | B68: 45664 | C68: Control | D68: South | E68: Desktop | F68: Organic | G68: Premium | H68: 1 | I68: 0 | J68: 0 | K68: 0 | L68: 0 | M68: 1 | N68: 0 | P68: 49.6 | Q68: =COUNTIF($A$2:A68,A68)>1 -> FALSE
A69: USR-100068 | B69: 45785 | C69: Control | D69: West | E69: Mobile | F69: Social | G69: Free | H69: 0 | I69: 0 | J69: 0 | K69: 0 | L69: 0 | M69: 0 | N69: 0 | P69: 60.4 | Q69: =COUNTIF($A$2:A69,A69)>1 -> FALSE
A70: USR-100069 | B70: 45735 | C70: Control | D70: East | E70: Desktop | F70: Email | G70: Free | H70: 1 | I70: 1 | J70: 1 | K70: 0 | L70: 0 | M70: 0 | N70: 0 | P70: 55.3 | Q70: =COUNTIF($A$2:A70,A70)>1 -> FALSE
A71: USR-100070 | B71: 45793 | C71: Control | D71: North | E71: Desktop | F71: Organic | G71: Free | H71: 0 | I71: 0 | J71: 0 | K71: 0 | L71: 0 | M71: 0 | N71: 0 | P71: 56.2 | Q71: =COUNTIF($A$2:A71,A71)>1 -> FALSE
A72: USR-100071 | B72: 45724 | C72: Control | D72: West | E72: Mobile | F72: Email | G72: Free | H72: 0 | I72: 0 | J72: 0 | K72: 0 | L72: 0 | M72: 0 | N72: 0 | P72: 29.4 | Q72: =COUNTIF($A$2:A72,A72)>1 -> FALSE
A73: USR-100072 | B73: 45724 | C73: Control | D73: East | E73: Mobile | F73: Email | G73: Free | H73: 1 | I73: 0 | J73: 0 | K73: 0 | L73: 0 | M73: 0 | N73: 0 | P73: 54.2 | Q73: =COUNTIF($A$2:A73,A73)>1 -> FALSE
... A79: USR-100078 | B79: 45673 | C79: Control | D79: North | E79: Mobile | F79: Organic | G79: Free | H79: 0 | I79: 0 | J79: 0 | K79: 0 | L79: 0 | M79: 2 | N79: 0 | P79: 48.4 | Q79: =COUNTIF($A$2:A79,A79)>1 -> FALSE
A80: USR-100079 | B80: 45708 | C80: Control | D80: West | E80: Desktop | F80: Organic | G80: Free | H80: 1 | I80: 1 | J80: 1 | K80: 1 | L80: 457.51 | M80: 0 | N80: 0 | O80: 7 | P80: 38 | Q80: =COUNTIF($A$2:A80,A80)>1 -> FALSE
A81: USR-100080 | B81: 45798 | C81: Control | D81: East | E81: Mobile | F81: Social | G81: Free | H81: 1 | I81: 0 | J81: 0 | K81: 0 | L81: 0 | M81: 0 | N81: 0 | P81: 44.2 | Q81: =COUNTIF($A$2:A81,A81)>1 -> FALSE
A82: USR-100081 | B82: 45785 | C82: Control | D82: South | E82: Mobile | F82: Organic | G82: Free | H82: 1 | I82: 1 | J82: 1 | K82: 0 | L82: 0 | M82: 0 | N82: 0 | P82: 81.2 | Q82: =COUNTIF($A$2:A82,A82)>1 -> FALSE
A83: USR-100082 | B83: 45724 | C83: Control | D83: South | E83: Mobile | F83: Referral | G83: Free | H83: 1 | I83: 1 | J83: 0 | K83: 0 | L83: 0 | M83: 0 | N83: 0 | P83: 63.8 | Q83: =COUNTIF($A$2:A83,A83)>1 -> FALSE
A84: USR-100083 | B84: 45748 | C84: Control | D84: South | E84: Desktop | F84: Email | G84: Free | H84: 0 | I84: 0 | J84: 0 | K84: 0 | L84: 0 | M84: 0 | N84: 0 | P84: 64.7 | Q84: =COUNTIF($A$2:A84,A84)>1 -> FALSE
A85: USR-100084 | B85: 45719 | C85: Control | D85: West | E85: Mobile | F85: Social | G85: Basic | H85: 0 | I85: 0 | J85: 0 | K85: 0 | L85: 0 | M85: 0 | N85: 0 | P85: 60.4 | Q85: =COUNTIF($A$2:A85,A85)>1 -> FALSE
A86: USR-100085 | B86: 45763 | C86: Control | D86: South | E86: Mobile | F86: Paid Search | G86: Free | H86: 0 | I86: 0 | J86: 0 | K86: 0 | L86: 0 | M86: 0 | N86: 0 | P86: 66.6 | Q86: =COUNTIF($A$2:A86,A86)>1 -> FALSE
A87: USR-100086 | B87: 45666 | C87: Control | D87: North | E87: Desktop | F87: Organic | G87: Free | H87: 1 | I87: 0 | J87: 0 | K87: 0 | L87: 0 | M87: 0 | N87: 0 | P87: 50.9 | Q87: =COUNTIF($A$2:A87,A87)>1 -> FALSE
A88: USR-100087 | B88: 45679 | C88: Control | D88: West | E88: Desktop | F88: Social | G88: Basic | H88: 0 | I88: 0 | J88: 0 | K88: 0 | L88: 0 | M88: 0 | N88: 0 | P88: 51 | Q88: =COUNTIF($A$2:A88,A88)>1 -> FALSE
A89: USR-100088 | B89: 45777 | C89: Control | D89: South | E89: Mobile | F89: Email | G89: Premium | H89: 0 | I89: 0 | J89: 0 | K89: 0 | L89: 0 | M89: 0 | N89: 0 | P89: 65.8 | Q89: =COUNTIF($A$2:A89,A89)>1 -> FALSE
A90: USR-100089 | B90: 45772 | C90: Control | D90: North | E90: Mobile | F90: Referral | G90: Basic | H90: 1 | I90: 0 | J90: 0 | K90: 0 | L90: 0 | M90: 0 | N90: 0 | P90: 61.8 | Q90: =COUNTIF($A$2:A90,A90)>1 -> FALSE
A91: USR-100090 | B91: 45689 | C91: Control | D91: North | E91: Mobile | F91: Organic | G91: Basic | H91: 1 | I91: 0 | J91: 0 | K91: 0 | L91: 0 | M91: 0 | N91: 0 | P91: 54.5 | Q91: =COUNTIF($A$2:A91,A91)>1 -> FALSE
...

Sheet business_context
A1: Item | B1: Description
A2: Business context | B2: A subscription product tested a new onboarding and activation campaign against the existing experience.
A3: Control | B3: Existing onboarding experience.
A4: Treatment | B4: New campaign experience.
A5: Primary decision | B5: Decide whether to launch, reject, continue testing, or launch only for selected segments.
A6: visited_landing_page | B6: 1 if the user visited the landing page after signup; otherwise 0.
A7: started_trial | B7: 1 if the user started a trial; otherwise 0.
A8: completed_onboarding | B8: 1 if the user completed onboarding; otherwise 0.
A9: converted_to_paid | B9: 1 if the user became a paid customer; otherwise 0.
A10: revenue_30d | B10: Revenue generated within 30 days of signup.
A11: support_tickets_30d | B11: Number of support tickets raised within 30 days.
A12: refund_requested | B12: 1 if the user requested a refund; otherwise 0.
... A14: Guardrail caution | B14: A better conversion rate may still be risky if refunds, support tickets, or low-quality revenue increase.

Sheet Missing_Values
A1: Column Name | B1: Missing Values
A2: user_id | B2: =COUNTBLANK(experiment_data!A2:A1409) -> 0
A3: signup_date | B3: =COUNTBLANK(experiment_data!B2:B1409) -> 0
A4: experiment_group | B4: =COUNTBLANK(experiment_data!C4:C1409) -> 0
A5: region | B5: =COUNTBLANK(experiment_data!D2:D1409) -> 0
A6: device_type | B6: =COUNTBLANK(experiment_data!E2:E1409) -> 18
A7: traffic_source | B7: =COUNTBLANK(experiment_data!F2:F1409) -> 24
A8: plan_type | B8: =COUNTBLANK(experiment_data!G2:G1409) -> 0
A9: visited_landing_page | B9: =COUNTBLANK(experiment_data!H2:H1409) -> 0
A10: started_trial | B10: =COUNTBLANK(experiment_data!I2:I1409) -> 0
A11: completed_onboarding | B11: =COUNTBLANK(experiment_data!J2:J1409) -> 0
A12: converted_to_paid | B12: =COUNTBLANK(experiment_data!K2:K1409) -> 0
A13: revenue_30d | B13: =COUNTBLANK(experiment_data!L2:L1409) -> 0
A14: support_tickets_30d | B14: =COUNTBLANK(experiment_data!M2:M1409) -> 0
A15: refund_requested | B15: =COUNTBLANK(experiment_data!N2:N1409) -> 0
A16: days_to_convert | B16: =COUNTBLANK(experiment_data!O2:O1409) -> 1336
A17: engagement_score | B17: =COUNTBLANK(experiment_data!P2:P1409) -> 14

Sheet Group_Counts
A1: Group | B1: Count
A2: Control Group | B2: =COUNTIF(experiment_data!C:C,"Control") -> 693
A3: Treatment Group | B3: =COUNTIF(experiment_data!C:C,"Treatment") -> 715

Sheet Duplicate_User_IDs
A2: Duplicate User ID | B2: Column1
A3: USR-100917
A4: USR-100433
A5: USR-101362
A6: USR-100096
A7: USR-101210
A8: USR-101232
A9: USR-101059
A10: USR-100541
A11: Total | B11: =COUNTA(A3:A10) -> 8

Sheet Invalid_binary_values
A1: Column | B1: Values
A2: visited_landing_page | B2: =IF(OR(experiment_data!H2:H1409=0,experiment_data!H:H=1),"Valid","Invalid") -> Valid
A3: started_trial | B3: =IF(OR(experiment_data!I:I=0,experiment_data!I:I=1),"Valid","Invalid") -> Valid
A4: completed_onboarding | B4: =IF(OR(experiment_data!J:J=0,experiment_data!J:J=1),"Valid","Invalid") -> Valid
A5: converted_to_paid | B5: =IF(OR(experiment_data!K:K=0,experiment_data!K:K=1),"Valid","Invalid") -> Valid
A6: days_to_convert | B6: =IF(OR(experiment_data!O:O=0,experiment_data!O:O=1),"Valid","Invalid") -> Valid

Sheet Outliers_in_revenue
A1: Revenue Outliers | B1: Column1
A2: Mean revenue | B2: =AVERAGE(experiment_data!$L:$L) -> 52.828828
A3: Std dev revenue | B3: =STDEV(experiment_data!$L:$L) -> 375.9367
A4: Outlier threshold (mean+3*std) | B4: =B2+3*B3 -> 1180.6389
A5: Outlier count | B5: =COUNTIF(experiment_data!L2:L1409,">"&0) -> 72
A6: Minimum revenue | B6: =MIN(experiment_data!L2:L1409) -> 0
A7: Maximum revenue | B7: =MAX(experiment_data!L2:L1410) -> 8610.72
A12: Column1 | B12: Column2
A13: Final Documentation Sheet
A15: Check | B15: Results
A16: Missing Values | B16: Device=18, Traffic=24, days_to_convert=1336, engagement_score=14
A17: Group Counts | B17: Control=693 , Treatment=715
A18: Duplicate User Ids | B18: 16 found
A19: Revenue Outliners | B19: Minimum Revenue:$0.00,Maximum revenue:$8610.72, Potential outliners indentified:27
A20: Segment Distribution | B20: Balanced

Sheet segment_dist._across_groups
A3: Count of experiment_group | B3: Column Labels
A4: Row Labels | B4: Control | C4: Treatment | D4: (blank) | E4: Grand Total
A5: Basic | B5: 223 | C5: 235 | E5: 458
A6: Free | B6: 361 | C6: 368 | E6: 729
A7: Premium | B7: 109 | C7: 112 | E7: 221
A8: (blank)
A9: Grand Total | B9: 693 | C9: 715 | E9: 1408
